<?xml version="1.0"?>
<robot xmlns:xacro="http://www.ros.org/wiki/xacro" name="simple_arm">

  <xacro:macro name="cyl_link" params="name length radius color:='0.3 0.7 1.0 1.0'">
    <link name="${name}">
      <visual>
        <origin xyz="0 0 ${length/2}" rpy="0 0 0"/>
        <geometry>
          <cylinder radius="${radius}" length="${length}"/>
        </geometry>
        <material name="${name}_color">
          <color rgba="${color}"/>
        </material>
      </visual>
      <collision>
        <origin xyz="0 0 ${length/2}" rpy="0 0 0"/>
        <geometry>
          <cylinder radius="${radius}" length="${length}"/>
        </geometry>
      </collision>
    </link>
  </xacro:macro>

  <link name="base_link">
    <visual>
      <geometry><box size="0.3 0.3 0.05"/></geometry>
      <material name="base_color"><color rgba="0.2 0.2 0.25 1.0"/></material>
    </visual>
  </link>

  <xacro:cyl_link name="link1" length="0.4" radius="0.04" color="0.4 0.7 1.0 1.0"/>
  <xacro:cyl_link name="link2" length="0.35" radius="0.035" color="0.5 0.8 0.5 1.0"/>
  <xacro:cyl_link name="link3" length="0.25" radius="0.03" color="1.0 0.6 0.3 1.0"/>

  <joint name="joint1" type="revolute">
    <parent link="base_link"/>
    <child link="link1"/>
    <origin xyz="0 0 0.025" rpy="0 0 0"/>
    <axis xyz="0 0 1"/>
    <limit lower="-3.14" upper="3.14" effort="10" velocity="2"/>
  </joint>

  <joint name="joint2" type="revolute">
    <parent link="link1"/>
    <child link="link2"/>
    <origin xyz="0 0 0.4" rpy="0 0 0"/>
    <axis xyz="0 1 0"/>
    <limit lower="-1.57" upper="1.57" effort="10" velocity="2"/>
  </joint>

  <joint name="joint3" type="revolute">
    <parent link="link2"/>
    <child link="link3"/>
    <origin xyz="0 0 0.35" rpy="0 0 0"/>
    <axis xyz="0 1 0"/>
    <limit lower="-1.57" upper="1.57" effort="10" velocity="2"/>
  </joint>

</robot>
